Workbook

Sheet HOME
A2: WISH2CARE SAFE HEALTH INTELLIGENCE SYSTEM
A3: School Assessment For Excellence | Student Health Screening & Scoring Platform
B6: PROGRAMME OVERVIEW
B7: This workbook screens students aged 7-30 in schools and colleges in 5-7 minutes per student. It produces an Overall Health Score, Nutrition Score, Undernutrition Risk Score, Lifestyle Score, Mental Wellness Score, Preventive Health Score and a School Health Index - all calculated automatically. This is a v1.0 instrument: pilot-test and statistically validate locally before using scores for clinical or policy decisions.
B11: NAVIGATE
B12: 1. STUDENT SCREENING
B13: Register students and capture the 7-section screening (Anthropometry, Diet, Lifestyle, Medical History, Mental Wellness, Clinical Observation, Preventive Health).
B14: 2. DOCTOR ASSESSMENT
B15: Doctor's diagnosis, advice, referral and follow-up decisions per student.
B16: 3. PARENT REPORT
B17: Printable one-page report per student: pick a Student ID, everything else fills in.
B18: 4. SCHOOL DASHBOARD
B19: Live cohort statistics, risk distribution and top health problems with charts.
B20: 5. RESEARCH DATABASE
... B29: COLOUR KEY - RISK BANDS
B30: 90+ Green Healthy | C30: 75-89 Light Green Mild Watch | D30: 60-74 Yellow Mild Risk | E30: 40-59 Orange Moderate Risk | F30: Below 40 Red High Risk
B32: Wish2Care Wellness Pvt Ltd | SAFE Programme | Confidential Student Health Data - handle per India DPDP Act 2023

Sheet STUDENT SCREENING
A1: STUDENT SCREENING | Wish2Care SAFE Health Intelligence System
A2: Student Registration | Q2: Section A - Anthropometry | W2: Section B - Diet | AD2: Section C - Lifestyle | AJ2: Section D - Medical History | AQ2: Section E - Mental Wellness | AU2: Section F - Clinical Observation | BA2: Section G - Preventive Health | BF2: Automated Scoring
A3: Student ID | B3: Screening Date | C3: School Name | D3: District | E3: State | F3: Class | G3: Division | H3: Roll Number | I3: Student Name | J3: Age | K3: Gender | L3: Date of Birth | M3: Parent Name | N3: Parent Mobile | O3: Emergency Contact | P3: Blood Group | Q3: Height (cm) | R3: Weight (kg) | S3: BMI | T3: BMI Category | U3: MUAC (cm) | V3: Waist Circumference (cm) | W3: Breakfast | X3: Fruit Intake | Y3: Vegetables | Z3: Protein Intake | AA3: Junk Food | AB3: Sugary Drinks | AC3: Water Intake | AD3: Physical Activity | AE3: Screen Time | AF3: Outdoor Play | AG3: Sleep Hours | AH3: Smoking | AI3: Alcohol | AJ3: Chronic Disease | AK3: Frequent Fever | AL3: Weight Loss | AM3: Poor Appetite | AN3: Repeated Infection | AO3: Hospitalisation | AP3: Medication | AQ3: Stress | AR3: Mood | AS3: Concentration | AT3: Bullying | AU3: Pallor | AV3: Dental Caries | AW3: Poor Oral Hygiene | AX3: Vision Problem | AY3: Hair Changes | AZ3: Skin Changes | BA3: Vaccination Complete | BB3: Deworming | BC3: Hand Hygiene | BD3: Dental Check-up | BE3: Vision Screening | BF3: Growth & Anthropometry Score | BG3: Diet Score | BH3: Lifestyle Score | BI3: Medical History Score | BJ3: Clinical Score | BK3: Mental Wellness Score | BL3: Preventive Score | BM3: Overall Health Score | BN3: Nutrition Score | BO3: Undernutrition Risk Score | BP3: Risk Category | BQ3: Need Referral | BR3: Need Doctor Review
A4: =IF(I4="","","STU"&TEXT(ROW()-3,"000000")) -> STU000001 | B4: 46204 | C4: Greenwood High | D4: Mumbai | E4: Maharashtra | F4: 8 | G4: A | H4: 12 | I4: Aarav Shah | J4: 13 | K4: Male | M4: Rakesh Shah | N4: 9876543210 | P4: B+ | Q4: 155 | R4: 45 | S4: =IF(OR(Q4="",R4=""),"",ROUND(R4/((Q4/100)^2),1)) -> 18.7 | T4: =IF(S4="","",IF(S4<18.5,"Underweight",IF(S4<25,"Normal",IF(S4<30,"Overweight","Obese")))) -> Normal | U4: 22 | V4: 60 | W4: Always | X4: Daily | Y4: Daily | Z4: Daily | AA4: Never | AB4: Never | AC4: More than 2L | AD4: Daily | AE4: Less than 2 hrs | AF4: Daily | AG4: 8+ hrs | AH4: Not Applicable | AI4: Not Applicable | AJ4: No | AK4: No | AL4: No | AM4: No | AN4: No | AO4: No | AP4: No | AQ4: Low | AR4: Happy | AS4: Good | AT4: No | AU4: No | AV4: No | AW4: No | AX4: No | AY4: No | AZ4: No | BA4: Yes | BB4: Yes | BC4: Good | BD4: Yes | BE4: Yes | BF4: =IF(T4="","",IF(T4="Normal",100,IF(T4="Overweight",65,IF(T4="Obese",50,IF(AND(U4<>"",U4<18.5),30,45))))) -> 100 | BG4: =IF(COUNTBLANK(W4:AC4)>0,"",ROUND(AVERAGE(INDEX('SCORING MASTER'!$D$5:$D$7,MATCH(W4,'SCORING MASTER'!$C$5:$C$7,0)),INDEX('SCORING MASTER'!$D$9:$D$11,MATCH(X4,'SCORING MASTER'!$C$9:$C$11,0)),INDEX('SCORING MASTER'!$D$13:$D$15,MATCH(Y4,'SCORING MASTER'!$C$13:$C$15,0)),INDEX('SCORING MASTER'!$D$17:$D$19,MATCH(Z4,'SCORING MASTER'!$C$17:$C$19,0)),INDEX('SCORING MASTER'!$D$21:$D$23,MATCH(AA4,'SCORING MASTER'!$C$21:$C$23,0)),INDEX('SCORING MASTER'!$D$25:$D$27,MATCH(AB4,'SCORING MASTER'!$C$25:$C$27,0)),INDEX('SCORING MASTER'!$D$29:$D$31,MATCH(AC4,'SCORING MASTER'!$C$29:$C$31,0)))*20,0)) -> 100 | BH4: =IF(COUNTBLANK(AD4:AI4)>0,"",ROUND(AVERAGE(INDEX('SCORING MASTER'!$D$33:$D$35,MATCH(AD4,'SCORING MASTER'!$C$33:$C$35,0)),INDEX('SCORING MASTER'!$D$37:$D$39,MATCH(AE4,'SCORING MASTER'!$C$37:$C$39,0)),INDEX('SCORING MASTER'!$D$41:$D$43,MATCH(AF4,'SCORING MASTER'!$C$41:$C$43,0)),INDEX('SCORING MASTER'!$D$45:$D$47,MATCH(AG4,'SCORING MASTER'!$C$45:$C$47,0)),INDEX('SCORING MASTER'!$D$49:$D$52,MATCH(AH4,'SCORING MASTER'!$C$49:$C$52,0)),INDEX('SCORING MASTER'!$D$54:$D$57,MATCH(AI4,'SCORING MASTER'!$C$54:$C$57,0)))*20,0)) -> 100 | BI4: =IF(COUNTBLANK(AJ4:AP4)>0,"",ROUND(AVERAGE(INDEX('SCORING MASTER'!$D$59:$D$60,MATCH(AJ4,'SCORING MASTER'!$C$59:$C$60,0)),INDEX('SCORING MASTER'!$D$62:$D$63,MATCH(AK4,'SCORING MASTER'!$C$62:$C$63,0)),INDEX('SCORING MASTER'!$D$65:$D$66,MATCH(AL4,'SCORING MASTER'!$C$65:$C$66,0)),INDEX('SCORING MASTER'!$D$68:$D$69,MATCH(AM4,'SCORING MASTER'!$C$68:$C$69,0)),INDEX('SCORING MASTER'!$D$71:$D$72,MATCH(AN4,'SCORING MASTER'!$C$71:$C$72,0)),INDEX('SCORING MASTER'!$D$74:$D$75,MATCH(AO4,'SCORING MASTER'!$C$74:$C$75,0)),INDEX('SCORING MASTER'!$D$77:$D$78,MATCH(AP4,'SCORING MASTER'!$C$77:$C$78,0)))*20,0)) -> 100 | BJ4: =IF(COUNTBLANK(AU4:AZ4)>0,"",ROUND(AVERAGE(INDEX('SCORING MASTER'!$D$95:$D$96,MATCH(AU4,'SCORING MASTER'!$C$95:$C$96,0)),INDEX('SCORING MASTER'!$D$98:$D$99,MATCH(AV4,'SCORING MASTER'!$C$98:$C$99,0)),INDEX('SCORING MASTER'!$D$101:$D$102,MATCH(AW4,'SCORING MASTER'!$C$101:$C$102,0)),INDEX('SCORING MASTER'!$D$104:$D$105,MATCH(AX4,'SCORING MASTER'!$C$104:$C$105,0)),INDEX('SCORING MASTER'!$D$107:$D$108,MATCH(AY4,'SCORING MASTER'!$C$107:$C$108,0)),INDEX('SCORING MASTER'!$D$110:$D$111,MATCH(AZ4,'SCORING MASTER'!$C$110:$C$111,0)))*20,0)) -> 100 | BK4: =IF(COUNTBLANK(AQ4:AT4)>0,"",ROUND(AVERAGE(INDEX('SCORING MASTER'!$D$80:$D$82,MATCH(AQ4,'SCORING MASTER'!$C$80:$C$82,0)),INDEX('SCORING MASTER'!$D$84:$D$86,MATCH(AR4,'SCORING MASTER'!$C$84:$C$86,0)),INDEX('SCORING MASTER'!$D$88:$D$90,MATCH(AS4,'SCORING MASTER'!$C$88:$C$90,0)),INDEX('SCORING MASTER'!$D$92:$D$93,MATCH(AT4,'SCORING MASTER'!$C$92:$C$93,0)))*20,0)) -> 100 | BL4: =IF(COUNTBLANK(BA4:BE4)>0,"",ROUND(AVERAGE(INDEX('SCORING MASTER'!$D$113:$D$115,MATCH(BA4,'SCORING MASTER'!$C$113:$C$115,0)),INDEX('SCORING MASTER'!$D$117:$D$119,MATCH(BB4,'SCORING MASTER'!$C$117:$C$119,0)),INDEX('SCORING MASTER'!$D$121:$D$123,MATCH(BC4,'SCORING MASTER'!$C$121:$C$123,0)),INDEX('SCORING MASTER'!$D$125:$D$126,MATCH(BD4,'SCORING MASTER'!$C$125:$C$126,0)),INDEX('SCORING MASTER'!$D$128:$D$129,MATCH(BE4,'SCORING MASTER'!$C$128:$C$129,0)))*20,0)) -> 100 | BM4: =IF(OR(BF4="",BG4="",BH4="",BI4="",BJ4="",BK4="",BL4=""),"",ROUND(BF4*0.25+BG4*0.2+BH4*0.15+BI4*0.15+BJ4*0.1+BK4*0.1+BL4*0.05,0)) -> 100 | BN4: =IF(OR(BF4="",BG4=""),"",ROUND(BF4*0.5+BG4*0.5,0)) -> 100 | BO4: =IF(BN4="","",ROUND(MIN(100,MAX(0,(100-BN4)+IF(AL4="Yes",15,0)+IF(AM4="Yes",15,0)+IF(AND(U4<>"",U4<18.5),20,0))),0)) -> 0 | BP4: =IF(BM4="","",IF(BM4>=90,"Green - Healthy",IF(BM4>=75,"Light Green - Mild Watch",IF(BM4>=60,"Yellow - Mild Risk",IF(BM4>=40,"Orange - Moderate Risk","Red - High Risk"))))) -> Green - Healthy | BQ4: =IF(BM4="","",IF(OR(BM4<60,BO4>=60,AJ4="Yes"),"Yes","No")) -> No | BR4: =IF(BM4="","",IF(OR(BP4="Orange - Moderate Risk",BP4="Red - High Risk",BQ4="Yes"),"Yes","No")) -> No
A5: =IF(I5="","","STU"&TEXT(ROW()-3,"000000")) -> STU000002 | B5: 46204 | C5: Greenwood High | D5: Mumbai | E5: Maharashtra | F5: 6 | G5: B | H5: 5 | I5: Priya Kadam | J5: 11 | K5: Female | M5: Sunita Kadam | N5: 9822011223 | P5: O+ | Q5: 128 | R5: 21 | S5: =IF(OR(Q5="",R5=""),"",ROUND(R5/((Q5/100)^2),1)) -> 12.8 | T5: =IF(S5="","",IF(S5<18.5,"Underweight",IF(S5<25,"Normal",IF(S5<30,"Overweight","Obese")))) -> Underweight | U5: 16 | V5: 48 | W5: Never | X5: Rarely | Y5: Rarely | Z5: Rarely | AA5: Daily | AB5: Daily | AC5: Less than 1L | AD5: Rarely | AE5: More than 4 hrs | AF5: Rarely | AG5: Less than 6 hrs | AH5: Not Applicable | AI5: Not Applicable | AJ5: No | AK5: Yes | AL5: Yes | AM5: Yes | AN5: Yes | AO5: No | AP5: No | AQ5: High | AR5: Low | AS5: Poor | AT5: Yes | AU5: Yes | AV5: Yes | AW5: Yes | AX5: No | AY5: Yes | AZ5: No | BA5: Partial | BB5: No | BC5: Poor | BD5: No | BE5: No | BF5: =IF(T5="","",IF(T5="Normal",100,IF(T5="Overweight",65,IF(T5="Obese",50,IF(AND(U5<>"",U5<18.5),30,45))))) -> 30 | BG5: =IF(COUNTBLANK(W5:AC5)>0,"",ROUND(AVERAGE(INDEX('SCORING MASTER'!$D$5:$D$7,MATCH(W5,'SCORING MASTER'!$C$5:$C$7,0)),INDEX('SCORING MASTER'!$D$9:$D$11,MATCH(X5,'SCORING MASTER'!$C$9:$C$11,0)),INDEX('SCORING MASTER'!$D$13:$D$15,MATCH(Y5,'SCORING MASTER'!$C$13:$C$15,0)),INDEX('SCORING MASTER'!$D$17:$D$19,MATCH(Z5,'SCORING MASTER'!$C$17:$C$19,0)),INDEX('SCORING MASTER'!$D$21:$D$23,MATCH(AA5,'SCORING MASTER'!$C$21:$C$23,0)),INDEX('SCORING MASTER'!$D$25:$D$27,MATCH(AB5,'SCORING MASTER'!$C$25:$C$27,0)),INDEX('SCORING MASTER'!$D$29:$D$31,MATCH(AC5,'SCORING MASTER'!$C$29:$C$31,0)))*20,0)) -> 0 | BH5: =IF(COUNTBLANK(AD5:AI5)>0,"",ROUND(AVERAGE(INDEX('SCORING MASTER'!$D$33:$D$35,MATCH(AD5,'SCORING MASTER'!$C$33:$C$35,0)),INDEX('SCORING MASTER'!$D$37:$D$39,MATCH(AE5,'SCORING MASTER'!$C$37:$C$39,0)),INDEX('SCORING MASTER'!$D$41:$D$43,MATCH(AF5,'SCORING MASTER'!$C$41:$C$43,0)),INDEX('SCORING MASTER'!$D$45:$D$47,MATCH(AG5,'SCORING MASTER'!$C$45:$C$47,0)),INDEX('SCORING MASTER'!$D$49:$D$52,MATCH(AH5,'SCORING MASTER'!$C$49:$C$52,0)),INDEX('SCORING MASTER'!$D$54:$D$57,MATCH(AI5,'SCORING MASTER'!$C$54:$C$57,0)))*20,0)) -> 33 | BI5: =IF(COUNTBLANK(AJ5:AP5)>0,"",ROUND(AVERAGE(INDEX('SCORING MASTER'!$D$59:$D$60,MATCH(AJ5,'SCORING MASTER'!$C$59:$C$60,0)),INDEX('SCORING MASTER'!$D$62:$D$63,MATCH(AK5,'SCORING MASTER'!$C$62:$C$63,0)),INDEX('SCORING MASTER'!$D$65:$D$66,MATCH(AL5,'SCORING MASTER'!$C$65:$C$66,0)),INDEX('SCORING MASTER'!$D$68:$D$69,MATCH(AM5,'SCORING MASTER'!$C$68:$C$69,0)),INDEX('SCORING MASTER'!$D$71:$D$72,MATCH(AN5,'SCORING MASTER'!$C$71:$C$72,0)),INDEX('SCORING MASTER'!$D$74:$D$75,MATCH(AO5,'SCORING MASTER'!$C$74:$C$75,0)),INDEX('SCORING MASTER'!$D$77:$D$78,MATCH(AP5,'SCORING MASTER'!$C$77:$C$78,0)))*20,0)) -> 43 | BJ5: =IF(COUNTBLANK(AU5:AZ5)>0,"",ROUND(AVERAGE(INDEX('SCORING MASTER'!$D$95:$D$96,MATCH(AU5,'SCORING MASTER'!$C$95:$C$96,0)),INDEX('SCORING MASTER'!$D$98:$D$99,MATCH(AV5,'SCORING MASTER'!$C$98:$C$99,0)),INDEX('SCORING MASTER'!$D$101:$D$102,MATCH(AW5,'SCORING MASTER'!$C$101:$C$102,0)),INDEX('SCORING MASTER'!$D$104:$D$105,MATCH(AX5,'SCORING MASTER'!$C$104:$C$105,0)),INDEX('SCORING MASTER'!$D$107:$D$108,MATCH(AY5,'SCORING MASTER'!$C$107:$C$108,0)),INDEX('SCORING MASTER'!$D$110:$D$111,MATCH(AZ5,'SCORING MASTER'!$C$110:$C$111,0)))*20,0)) -> 33 | BK5: =IF(COUNTBLANK(AQ5:AT5)>0,"",ROUND(AVERAGE(INDEX('SCORING MASTER'!$D$80:$D$82,MATCH(AQ5,'SCORING MASTER'!$C$80:$C$82,0)),INDEX('SCORING MASTER'!$D$84:$D$86,MATCH(AR5,'SCORING MASTER'!$C$84:$C$86,0)),INDEX('SCORING MASTER'!$D$88:$D$90,MATCH(AS5,'SCORING MASTER'!$C$88:$C$90,0)),INDEX('SCORING MASTER'!$D$92:$D$93,MATCH(AT5,'SCORING MASTER'!$C$92:$C$93,0)))*20,0)) -> 0 | BL5: =IF(COUNTBLANK(BA5:BE5)>0,"",ROUND(AVERAGE(INDEX('SCORING MASTER'!$D$113:$D$115,MATCH(BA5,'SCORING MASTER'!$C$113:$C$115,0)),INDEX('SCORING MASTER'!$D$117:$D$119,MATCH(BB5,'SCORING MASTER'!$C$117:$C$119,0)),INDEX('SCORING MASTER'!$D$121:$D$123,MATCH(BC5,'SCORING MASTER'!$C$121:$C$123,0)),INDEX('SCORING MASTER'!$D$125:$D$126,MATCH(BD5,'SCORING MASTER'!$C$125:$C$126,0)),INDEX('SCORING MASTER'!$D$128:$D$129,MATCH(BE5,'SCORING MASTER'!$C$128:$C$129,0)))*20,0)) -> 12 | BM5: =IF(OR(BF5="",BG5="",BH5="",BI5="",BJ5="",BK5="",BL5=""),"",ROUND(BF5*0.25+BG5*0.2+BH5*0.15+BI5*0.15+BJ5*0.1+BK5*0.1+BL5*0.05,0)) -> 23 | BN5: =IF(OR(BF5="",BG5=""),"",ROUND(BF5*0.5+BG5*0.5,0)) -> 15 | BO5: =IF(BN5="","",ROUND(MIN(100,MAX(0,(100-BN5)+IF(AL5="Yes",15,0)+IF(AM5="Yes",15,0)+IF(AND(U5<>"",U5<18.5),20,0))),0)) -> 100 | BP5: =IF(BM5="","",IF(BM5>=90,"Green - Healthy",IF(BM5>=75,"Light Green - Mild Watch",IF(BM5>=60,"Yellow - Mild Risk",IF(BM5>=40,"Orange - Moderate Risk","Red - High Risk"))))) -> Red - High Risk | BQ5: =IF(BM5="","",IF(OR(BM5<60,BO5>=60,AJ5="Yes"),"Yes","No")) -> Yes | BR5: =IF(BM5="","",IF(OR(BP5="Orange - Moderate Risk",BP5="Red - High Risk",BQ5="Yes"),"Yes","No")) -> Yes
A6: =IF(I6="","","STU"&TEXT(ROW()-3,"000000")) -> STU000003 | B6: 46204 | C6: St. Xavier's College | D6: Pune | E6: Maharashtra | F6: UG-2 | G6: C | H6: 45 | I6: Rohan Deshmukh | J6: 19 | K6: Male | M6: Vijay Deshmukh | N6: 9765432109 | P6: A+ | Q6: 172 | R6: 88 | S6: =IF(OR(Q6="",R6=""),"",ROUND(R6/((Q6/100)^2),1)) -> 29.7 | T6: =IF(S6="","",IF(S6<18.5,"Underweight",IF(S6<25,"Normal",IF(S6<30,"Overweight","Obese")))) -> Overweight | U6: 27 | V6: 98 | W6: Sometimes | X6: 3-5 per week | Y6: Sometimes | Z6: Daily | AA6: Weekly | AB6: Weekly | AC6: 1-2L | AD6: Rarely | AE6: More than 4 hrs | AF6: Rarely | AG6: Less than 6 hrs | AH6: Occasional | AI6: Occasional | AJ6: No | AK6: No | AL6: No | AM6: No | AN6: No | AO6: No | AP6: No | AQ6: High | AR6: Neutral | AS6: Average | AT6: No | AU6: No | AV6: Yes | AW6: No | AX6: Yes | AY6: No | AZ6: No | BA6: Yes | BB6: Yes | BC6: Average | BD6: No | BE6: No | BF6: =IF(T6="","",IF(T6="Normal",100,IF(T6="Overweight",65,IF(T6="Obese",50,IF(AND(U6<>"",U6<18.5),30,45))))) -> 65 | BG6: =IF(COUNTBLANK(W6:AC6)>0,"",ROUND(AVERAGE(INDEX('SCORING MASTER'!$D$5:$D$7,MATCH(W6,'SCORING MASTER'!$C$5:$C$7,0)),INDEX('SCORING MASTER'!$D$9:$D$11,MATCH(X6,'SCORING MASTER'!$C$9:$C$11,0)),INDEX('SCORING MASTER'!$D$13:$D$15,MATCH(Y6,'SCORING MASTER'!$C$13:$C$15,0)),INDEX('SCORING MASTER'!$D$17:$D$19,MATCH(Z6,'SCORING MASTER'!$C$17:$C$19,0)),INDEX('SCORING MASTER'!$D$21:$D$23,MATCH(AA6,'SCORING MASTER'!$C$21:$C$23,0)),INDEX('SCORING MASTER'!$D$25:$D$27,MATCH(AB6,'SCORING MASTER'!$C$25:$C$27,0)),INDEX('SCORING MASTER'!$D$29:$D$31,MATCH(AC6,'SCORING MASTER'!$C$29:$C$31,0)))*20,0)) -> 66 | BH6: =IF(COUNTBLANK(AD6:AI6)>0,"",ROUND(AVERAGE(INDEX('SCORING MASTER'!$D$33:$D$35,MATCH(AD6,'SCORING MASTER'!$C$33:$C$35,0)),INDEX('SCORING MASTER'!$D$37:$D$39,MATCH(AE6,'SCORING MASTER'!$C$37:$C$39,0)),INDEX('SCORING MASTER'!$D$41:$D$43,MATCH(AF6,'SCORING MASTER'!$C$41:$C$43,0)),INDEX('SCORING MASTER'!$D$45:$D$47,MATCH(AG6,'SCORING MASTER'!$C$45:$C$47,0)),INDEX('SCORING MASTER'!$D$49:$D$52,MATCH(AH6,'SCORING MASTER'!$C$49:$C$52,0)),INDEX('SCORING MASTER'!$D$54:$D$57,MATCH(AI6,'SCORING MASTER'!$C$54:$C$57,0)))*20,0)) -> 13 | BI6: =IF(COUNTBLANK(AJ6:AP6)>0,"",ROUND(AVERAGE(INDEX('SCORING MASTER'!$D$59:$D$60,MATCH(AJ6,'SCORING MASTER'!$C$59:$C$60,0)),INDEX('SCORING MASTER'!$D$62:$D$63,MATCH(AK6,'SCORING MASTER'!$C$62:$C$63,0)),INDEX('SCORING MASTER'!$D$65:$D$66,MATCH(AL6,'SCORING MASTER'!$C$65:$C$66,0)),INDEX('SCORING MASTER'!$D$68:$D$69,MATCH(AM6,'SCORING MASTER'!$C$68:$C$69,0)),INDEX('SCORING MASTER'!$D$71:$D$72,MATCH(AN6,'SCORING MASTER'!$C$71:$C$72,0)),INDEX('SCORING MASTER'!$D$74:$D$75,MATCH(AO6,'SCORING MASTER'!$C$74:$C$75,0)),INDEX('SCORING MASTER'!$D$77:$D$78,MATCH(AP6,'SCORING MASTER'!$C$77:$C$78,0)))*20,0)) -> 100 | BJ6: =IF(COUNTBLANK(AU6:AZ6)>0,"",ROUND(AVERAGE(INDEX('SCORING MASTER'!$D$95:$D$96,MATCH(AU6,'SCORING MASTER'!$C$95:$C$96,0)),INDEX('SCORING MASTER'!$D$98:$D$99,MATCH(AV6,'SCORING MASTER'!$C$98:$C$99,0)),INDEX('SCORING MASTER'!$D$101:$D$102,MATCH(AW6,'SCORING MASTER'!$C$101:$C$102,0)),INDEX('SCORING MASTER'!$D$104:$D$105,MATCH(AX6,'SCORING MASTER'!$C$104:$C$105,0)),INDEX('SCORING MASTER'!$D$107:$D$108,MATCH(AY6,'SCORING MASTER'!$C$107:$C$108,0)),INDEX('SCORING MASTER'!$D$110:$D$111,MATCH(AZ6,'SCORING MASTER'!$C$110:$C$111,0)))*20,0)) -> 67 | BK6: =IF(COUNTBLANK(AQ6:AT6)>0,"",ROUND(AVERAGE(INDEX('SCORING MASTER'!$D$80:$D$82,MATCH(AQ6,'SCORING MASTER'!$C$80:$C$82,0)),INDEX('SCORING MASTER'!$D$84:$D$86,MATCH(AR6,'SCORING MASTER'!$C$84:$C$86,0)),INDEX('SCORING MASTER'!$D$88:$D$90,MATCH(AS6,'SCORING MASTER'!$C$88:$C$90,0)),INDEX('SCORING MASTER'!$D$92:$D$93,MATCH(AT6,'SCORING MASTER'!$C$92:$C$93,0)))*20,0)) -> 55 | BL6: =IF(COUNTBLANK(BA6:BE6)>0,"",ROUND(AVERAGE(INDEX('SCORING MASTER'!$D$113:$D$115,MATCH(BA6,'SCORING MASTER'!$C$113:$C$115,0)),INDEX('SCORING MASTER'!$D$117:$D$119,MATCH(BB6,'SCORING MASTER'!$C$117:$C$119,0)),INDEX('SCORING MASTER'!$D$121:$D$123,MATCH(BC6,'SCORING MASTER'!$C$121:$C$123,0)),INDEX('SCORING MASTER'!$D$125:$D$126,MATCH(BD6,'SCORING MASTER'!$C$125:$C$126,0)),INDEX('SCORING MASTER'!$D$128:$D$129,MATCH(BE6,'SCORING MASTER'!$C$128:$C$129,0)))*20,0)) -> 52 | BM6: =IF(OR(BF6="",BG6="",BH6="",BI6="",BJ6="",BK6="",BL6=""),"",ROUND(BF6*0.25+BG6*0.2+BH6*0.15+BI6*0.15+BJ6*0.1+BK6*0.1+BL6*0.05,0)) -> 61 | BN6: =IF(OR(BF6="",BG6=""),"",ROUND(BF6*0.5+BG6*0.5,0)) -> 66 | BO6: =IF(BN6="","",ROUND(MIN(100,MAX(0,(100-BN6)+IF(AL6="Yes",15,0)+IF(AM6="Yes",15,0)+IF(AND(U6<>"",U6<18.5),20,0))),0)) -> 34 | BP6: =IF(BM6="","",IF(BM6>=90,"Green - Healthy",IF(BM6>=75,"Light Green - Mild Watch",IF(BM6>=60,"Yellow - Mild Risk",IF(BM6>=40,"Orange - Moderate Risk","Red - High Risk"))))) -> Yellow - Mild Risk | BQ6: =IF(BM6="","",IF(OR(BM6<60,BO6>=60,AJ6="Yes"),"Yes","No")) -> No | BR6: =IF(BM6="","",IF(OR(BP6="Orange - Moderate Risk",BP6="Red - High Risk",BQ6="Yes"),"Yes","No")) -> No
A7: =IF(I7="","","STU"&TEXT(ROW()-3,"000000")) -> STU000004 | B7: 46204 | C7: St. Xavier's College | D7: Pune | E7: Maharashtra | F7: UG-1 | G7: A | H7: 8 | I7: Sneha Iyer | J7: 18 | K7: Female | M7: Lakshmi Iyer | N7: 9900112233 | P7: AB+ | Q7: 160 | R7: 54 | S7: =IF(OR(Q7="",R7=""),"",ROUND(R7/((Q7/100)^2),1)) -> 21.1 | T7: =IF(S7="","",IF(S7<18.5,"Underweight",IF(S7<25,"Normal",IF(S7<30,"Overweight","Obese")))) -> Normal | U7: 24 | V7: 70 | W7: Always | X7: 3-5 per week | Y7: Daily | Z7: 3-5 per week | AA7: Weekly | AB7: Never | AC7: 1-2L | AD7: 3-5 per week | AE7: 2-4 hrs | AF7: 3-5 per week | AG7: 6-8 hrs | AH7: Never | AI7: Never | AJ7: No | AK7: No | AL7: No | AM7: No | AN7: No | AO7: No | AP7: No | AQ7: Moderate | AR7: Neutral | AS7: Average | AT7: No | AU7: No | AV7: No | AW7: No | AX7: No | AY7: No | AZ7: No | BA7: Yes | BB7: Yes | BC7: Good | BD7: Yes | BE7: Yes | BF7: =IF(T7="","",IF(T7="Normal",100,IF(T7="Overweight",65,IF(T7="Obese",50,IF(AND(U7<>"",U7<18.5),30,45))))) -> 100 | BG7: =IF(COUNTBLANK(W7:AC7)>0,"",ROUND(AVERAGE(INDEX('SCORING MASTER'!$D$5:$D$7,MATCH(W7,'SCORING MASTER'!$C$5:$C$7,0)),INDEX('SCORING MASTER'!$D$9:$D$11,MATCH(X7,'SCORING MASTER'!$C$9:$C$11,0)),INDEX('SCORING MASTER'!$D$13:$D$15,MATCH(Y7,'SCORING MASTER'!$C$13:$C$15,0)),INDEX('SCORING MASTER'!$D$17:$D$19,MATCH(Z7,'SCORING MASTER'!$C$17:$C$19,0)),INDEX('SCORING MASTER'!$D$21:$D$23,MATCH(AA7,'SCORING MASTER'!$C$21:$C$23,0)),INDEX('SCORING MASTER'!$D$25:$D$27,MATCH(AB7,'SCORING MASTER'!$C$25:$C$27,0)),INDEX('SCORING MASTER'!$D$29:$D$31,MATCH(AC7,'SCORING MASTER'!$C$29:$C$31,0)))*20,0)) -> 77 | BH7: =IF(COUNTBLANK(AD7:AI7)>0,"",ROUND(AVERAGE(INDEX('SCORING MASTER'!$D$33:$D$35,MATCH(AD7,'SCORING MASTER'!$C$33:$C$35,0)),INDEX('SCORING MASTER'!$D$37:$D$39,MATCH(AE7,'SCORING MASTER'!$C$37:$C$39,0)),INDEX('SCORING MASTER'!$D$41:$D$43,MATCH(AF7,'SCORING MASTER'!$C$41:$C$43,0)),INDEX('SCORING MASTER'!$D$45:$D$47,MATCH(AG7,'SCORING MASTER'!$C$45:$C$47,0)),INDEX('SCORING MASTER'!$D$49:$D$52,MATCH(AH7,'SCORING MASTER'!$C$49:$C$52,0)),INDEX('SCORING MASTER'!$D$54:$D$57,MATCH(AI7,'SCORING MASTER'!$C$54:$C$57,0)))*20,0)) -> 73 | BI7: =IF(COUNTBLANK(AJ7:AP7)>0,"",ROUND(AVERAGE(INDEX('SCORING MASTER'!$D$59:$D$60,MATCH(AJ7,'SCORING MASTER'!$C$59:$C$60,0)),INDEX('SCORING MASTER'!$D$62:$D$63,MATCH(AK7,'SCORING MASTER'!$C$62:$C$63,0)),INDEX('SCORING MASTER'!$D$65:$D$66,MATCH(AL7,'SCORING MASTER'!$C$65:$C$66,0)),INDEX('SCORING MASTER'!$D$68:$D$69,MATCH(AM7,'SCORING MASTER'!$C$68:$C$69,0)),INDEX('SCORING MASTER'!$D$71:$D$72,MATCH(AN7,'SCORING MASTER'!$C$71:$C$72,0)),INDEX('SCORING MASTER'!$D$74:$D$75,MATCH(AO7,'SCORING MASTER'!$C$74:$C$75,0)),INDEX('SCORING MASTER'!$D$77:$D$78,MATCH(AP7,'SCORING MASTER'!$C$77:$C$78,0)))*20,0)) -> 100 | BJ7: =IF(COUNTBLANK(AU7:AZ7)>0,"",ROUND(AVERAGE(INDEX('SCORING MASTER'!$D$95:$D$96,MATCH(AU7,'SCORING MASTER'!$C$95:$C$96,0)),INDEX('SCORING MASTER'!$D$98:$D$99,MATCH(AV7,'SCORING MASTER'!$C$98:$C$99,0)),INDEX('SCORING MASTER'!$D$101:$D$102,MATCH(AW7,'SCORING MASTER'!$C$101:$C$102,0)),INDEX('SCORING MASTER'!$D$104:$D$105,MATCH(AX7,'SCORING MASTER'!$C$104:$C$105,0)),INDEX('SCORING MASTER'!$D$107:$D$108,MATCH(AY7,'SCORING MASTER'!$C$107:$C$108,0)),INDEX('SCORING MASTER'!$D$110:$D$111,MATCH(AZ7,'SCORING MASTER'!$C$110:$C$111,0)))*20,0)) -> 100 | BK7: =IF(COUNTBLANK(AQ7:AT7)>0,"",ROUND(AVERAGE(INDEX('SCORING MASTER'!$D$80:$D$82,MATCH(AQ7,'SCORING MASTER'!$C$80:$C$82,0)),INDEX('SCORING MASTER'!$D$84:$D$86,MATCH(AR7,'SCORING MASTER'!$C$84:$C$86,0)),INDEX('SCORING MASTER'!$D$88:$D$90,MATCH(AS7,'SCORING MASTER'!$C$88:$C$90,0)),INDEX('SCORING MASTER'!$D$92:$D$93,MATCH(AT7,'SCORING MASTER'!$C$92:$C$93,0)))*20,0)) -> 70 | BL7: =IF(COUNTBLANK(BA7:BE7)>0,"",ROUND(AVERAGE(INDEX('SCORING MASTER'!$D$113:$D$115,MATCH(BA7,'SCORING MASTER'!$C$113:$C$115,0)),INDEX('SCORING MASTER'!$D$117:$D$119,MATCH(BB7,'SCORING MASTER'!$C$117:$C$119,0)),INDEX('SCORING MASTER'!$D$121:$D$123,MATCH(BC7,'SCORING MASTER'!$C$121:$C$123,0)),INDEX('SCORING MASTER'!$D$125:$D$126,MATCH(BD7,'SCORING MASTER'!$C$125:$C$126,0)),INDEX('SCORING MASTER'!$D$128:$D$129,MATCH(BE7,'SCORING MASTER'!$C$128:$C$129,0)))*20,0)) -> 100 | BM7: =IF(OR(BF7="",BG7="",BH7="",BI7="",BJ7="",BK7="",BL7=""),"",ROUND(BF7*0.25+BG7*0.2+BH7*0.15+BI7*0.15+BJ7*0.1+BK7*0.1+BL7*0.05,0)) -> 88 | BN7: =IF(OR(BF7="",BG7=""),"",ROUND(BF7*0.5+BG7*0.5,0)) -> 89 | BO7: =IF(BN7="","",ROUND(MIN(100,MAX(0,(100-BN7)+IF(AL7="Yes",15,0)+IF(AM7="Yes",15,0)+IF(AND(U7<>"",U7<18.5),20,0))),0)) -> 11 | BP7: =IF(BM7="","",IF(BM7>=90,"Green - Healthy",IF(BM7>=75,"Light Green - Mild Watch",IF(BM7>=60,"Yellow - Mild Risk",IF(BM7>=40,"Orange - Moderate Risk","Red - High Risk"))))) -> Light Green - Mild Watch | BQ7: =IF(BM7="","",IF(OR(BM7<60,BO7>=60,AJ7="Yes"),"Yes","No")) -> No | BR7: =IF(BM7="","",IF(OR(BP7="Orange - Moderate Risk",BP7="Red - High Risk",BQ7="Yes"),"Yes","No")) -> No
A8: =IF(I8="","","STU"&TEXT(ROW()-3,"000000")) -> STU000005 | B8: 46204 | C8: Delhi Public School | D8: South Delhi | E8: Delhi | F8: 10 | G8: A | H8: 21 | I8: Kabir Mehta | J8: 15 | K8: Male | M8: Anil Mehta | N8: 9811122233 | P8: B- | Q8: 163 | R8: 72 | S8: =IF(OR(Q8="",R8=""),"",ROUND(R8/((Q8/100)^2),1)) -> 27.1 | T8: =IF(S8="","",IF(S8<18.5,"Underweight",IF(S8<25,"Normal",IF(S8<30,"Overweight","Obese")))) -> Overweight | U8: 25 | V8: 88 | W8: Sometimes | X8: Rarely | Y8: Rarely | Z8: Daily | AA8: Daily | AB8: Daily | AC8: 1-2L | AD8: Rarely | AE8: More than 4 hrs | AF8: Rarely | AG8: Less than 6 hrs | AH8: Not Applicable | AI8: Not Applicable | AJ8: No | AK8: No | AL8: No | AM8: No | AN8: No | AO8: No | AP8: No | AQ8: High | AR8: Low | AS8: Poor | AT8: No | AU8: No | AV8: Yes | AW8: Yes | AX8: No | AY8: No | AZ8: No | BA8: Yes | BB8: Yes | BC8: Average | BD8: No | BE8: No | BF8: =IF(T8="","",IF(T8="Normal",100,IF(T8="Overweight",65,IF(T8="Obese",50,IF(AND(U8<>"",U8<18.5),30,45))))) -> 65 | BG8: =IF(COUNTBLANK(W8:AC8)>0,"",ROUND(AVERAGE(INDEX('SCORING MASTER'!$D$5:$D$7,MATCH(W8,'SCORING MASTER'!$C$5:$C$7,0)),INDEX('SCORING MASTER'!$D$9:$D$11,MATCH(X8,'SCORING MASTER'!$C$9:$C$11,0)),INDEX('SCORING MASTER'!$D$13:$D$15,MATCH(Y8,'SCORING MASTER'!$C$13:$C$15,0)),INDEX('SCORING MASTER'!$D$17:$D$19,MATCH(Z8,'SCORING MASTER'!$C$17:$C$19,0)),INDEX('SCORING MASTER'!$D$21:$D$23,MATCH(AA8,'SCORING MASTER'!$C$21:$C$23,0)),INDEX('SCORING MASTER'!$D$25:$D$27,MATCH(AB8,'SCORING MASTER'!$C$25:$C$27,0)),INDEX('SCORING MASTER'!$D$29:$D$31,MATCH(AC8,'SCORING MASTER'!$C$29:$C$31,0)))*20,0)) -> 31 | BH8: =IF(COUNTBLANK(AD8:AI8)>0,"",ROUND(AVERAGE(INDEX('SCORING MASTER'!$D$33:$D$35,MATCH(AD8,'SCORING MASTER'!$C$33:$C$35,0)),INDEX('SCORING MASTER'!$D$37:$D$39,MATCH(AE8,'SCORING MASTER'!$C$37:$C$39,0)),INDEX('SCORING MASTER'!$D$41:$D$43,MATCH(AF8,'SCORING MASTER'!$C$41:$C$43,0)),INDEX('SCORING MASTER'!$D$45:$D$47,MATCH(AG8,'SCORING MASTER'!$C$45:$C$47,0)),INDEX('SCORING MASTER'!$D$49:$D$52,MATCH(AH8,'SCORING MASTER'!$C$49:$C$52,0)),INDEX('SCORING MASTER'!$D$54:$D$57,MATCH(AI8,'SCORING MASTER'!$C$54:$C$57,0)))*20,0)) -> 33 | BI8: =IF(COUNTBLANK(AJ8:AP8)>0,"",ROUND(AVERAGE(INDEX('SCORING MASTER'!$D$59:$D$60,MATCH(AJ8,'SCORING MASTER'!$C$59:$C$60,0)),INDEX('SCORING MASTER'!$D$62:$D$63,MATCH(AK8,'SCORING MASTER'!$C$62:$C$63,0)),INDEX('SCORING MASTER'!$D$65:$D$66,MATCH(AL8,'SCORING MASTER'!$C$65:$C$66,0)),INDEX('SCORING MASTER'!$D$68:$D$69,MATCH(AM8,'SCORING MASTER'!$C$68:$C$69,0)),INDEX('SCORING MASTER'!$D$71:$D$72,MATCH(AN8,'SCORING MASTER'!$C$71:$C$72,0)),INDEX('SCORING MASTER'!$D$74:$D$75,MATCH(AO8,'SCORING MASTER'!$C$74:$C$75,0)),INDEX('SCORING MASTER'!$D$77:$D$78,MATCH(AP8,'SCORING MASTER'!$C$77:$C$78,0)))*20,0)) -> 100 | BJ8: =IF(COUNTBLANK(AU8:AZ8)>0,"",ROUND(AVERAGE(INDEX('SCORING MASTER'!$D$95:$D$96,MATCH(AU8,'SCORING MASTER'!$C$95:$C$96,0)),INDEX('SCORING MASTER'!$D$98:$D$99,MATCH(AV8,'SCORING MASTER'!$C$98:$C$99,0)),INDEX('SCORING MASTER'!$D$101:$D$102,MATCH(AW8,'SCORING MASTER'!$C$101:$C$102,0)),INDEX('SCORING MASTER'!$D$104:$D$105,MATCH(AX8,'SCORING MASTER'!$C$104:$C$105,0)),INDEX('SCORING MASTER'!$D$107:$D$108,MATCH(AY8,'SCORING MASTER'!$C$107:$C$108,0)),INDEX('SCORING MASTER'!$D$110:$D$111,MATCH(AZ8,'SCORING MASTER'!$C$110:$C$111,0)))*20,0)) -> 67 | BK8: =IF(COUNTBLANK(AQ8:AT8)>0,"",ROUND(AVERAGE(INDEX('SCORING MASTER'!$D$80:$D$82,MATCH(AQ8,'SCORING MASTER'!$C$80:$C$82,0)),INDEX('SCORING MASTER'!$D$84:$D$86,MATCH(AR8,'SCORING MASTER'!$C$84:$C$86,0)),INDEX('SCORING MASTER'!$D$88:$D$90,MATCH(AS8,'SCORING MASTER'!$C$88:$C$90,0)),INDEX('SCORING MASTER'!$D$92:$D$93,MATCH(AT8,'SCORING MASTER'!$C$92:$C$93,0)))*20,0)) -> 25 | BL8: =IF(COUNTBLANK(BA8:BE8)>0,"",ROUND(AVERAGE(INDEX('SCORING MASTER'!$D$113:$D$115,MATCH(BA8,'SCORING MASTER'!$C$113:$C$115,0)),INDEX('SCORING MASTER'!$D$117:$D$119,MATCH(BB8,'SCORING MASTER'!$C$117:$C$119,0)),INDEX('SCORING MASTER'!$D$121:$D$123,MATCH(BC8,'SCORING MASTER'!$C$121:$C$123,0)),INDEX('SCORING MASTER'!$D$125:$D$126,MATCH(BD8,'SCORING MASTER'!$C$125:$C$126,0)),INDEX('SCORING MASTER'!$D$128:$D$129,MATCH(BE8,'SCORING MASTER'!$C$128:$C$129,0)))*20,0)) -> 52 | BM8: =IF(OR(BF8="",BG8="",BH8="",BI8="",BJ8="",BK8="",BL8=""),"",ROUND(BF8*0.25+BG8*0.2+BH8*0.15+BI8*0.15+BJ8*0.1+BK8*0.1+BL8*0.05,0)) -> 54 | BN8: =IF(OR(BF8="",BG8=""),"",ROUND(BF8*0.5+BG8*0.5,0)) -> 48 | BO8: =IF(BN8="","",ROUND(MIN(100,MAX(0,(100-BN8)+IF(AL8="Yes",15,0)+IF(AM8="Yes",15,0)+IF(AND(U8<>"",U8<18.5),20,0))),0)) -> 52 | BP8: =IF(BM8="","",IF(BM8>=90,"Green - Healthy",IF(BM8>=75,"Light Green - Mild Watch",IF(BM8>=60,"Yellow - Mild Risk",IF(BM8>=40,"Orange - Moderate Risk","Red - High Risk"))))) -> Orange - Moderate Risk | BQ8: =IF(BM8="","",IF(OR(BM8<60,BO8>=60,AJ8="Yes"),"Yes","No")) -> Yes | BR8: =IF(BM8="","",IF(OR(BP8="Orange - Moderate Risk",BP8="Red - High Risk",BQ8="Yes"),"Yes","No")) -> Yes
A9: =IF(I9="","","STU"&TEXT(ROW()-3,"000000")) -> STU000006 | B9: 46204 | C9: Delhi Public School | D9: South Delhi | E9: Delhi | F9: 9 | G9: B | H9: 3 | I9: Ananya Verma | J9: 14 | K9: Female | M9: Deepa Verma | N9: 9871234567 | P9: O- | Q9: 150 | R9: 38 | S9: =IF(OR(Q9="",R9=""),"",ROUND(R9/((Q9/100)^2),1)) -> 16.9 | T9: =IF(S9="","",IF(S9<18.5,"Underweight",IF(S9<25,"Normal",IF(S9<30,"Overweight","Obese")))) -> Underweight | U9: 19 | V9: 58 | W9: Always | X9: Daily | Y9: Daily | Z9: 3-5 per week | AA9: Weekly | AB9: Weekly | AC9: More than 2L | AD9: Daily | AE9: 2-4 hrs | AF9: Daily | AG9: 8+ hrs | AH9: Not Applicable | AI9: Not Applicable | AJ9: No | AK9: No | AL9: No | AM9: No | AN9: No | AO9: No | AP9: No | AQ9: Low | AR9: Happy | AS9: Good | AT9: No | AU9: No | AV9: No | AW9: No | AX9: No | AY9: No | AZ9: No | BA9: Yes | BB9: Yes | BC9: Good | BD9: Yes | BE9: Yes | BF9: =IF(T9="","",IF(T9="Normal",100,IF(T9="Overweight",65,IF(T9="Obese",50,IF(AND(U9<>"",U9<18.5),30,45))))) -> 45 | BG9: =IF(COUNTBLANK(W9:AC9)>0,"",ROUND(AVERAGE(INDEX('SCORING MASTER'!$D$5:$D$7,MATCH(W9,'SCORING MASTER'!$C$5:$C$7,0)),INDEX('SCORING MASTER'!$D$9:$D$11,MATCH(X9,'SCORING MASTER'!$C$9:$C$11,0)),INDEX('SCORING MASTER'!$D$13:$D$15,MATCH(Y9,'SCORING MASTER'!$C$13:$C$15,0)),INDEX('SCORING MASTER'!$D$17:$D$19,MATCH(Z9,'SCORING MASTER'!$C$17:$C$19,0)),INDEX('SCORING MASTER'!$D$21:$D$23,MATCH(AA9,'SCORING MASTER'!$C$21:$C$23,0)),INDEX('SCORING MASTER'!$D$25:$D$27,MATCH(AB9,'SCORING MASTER'!$C$25:$C$27,0)),INDEX('SCORING MASTER'!$D$29:$D$31,MATCH(AC9,'SCORING MASTER'!$C$29:$C$31,0)))*20,0)) -> 83 | BH9: =IF(COUNTBLANK(AD9:AI9)>0,"",ROUND(AVERAGE(INDEX('SCORING MASTER'!$D$33:$D$35,MATCH(AD9,'SCORING MASTER'!$C$33:$C$35,0)),INDEX('SCORING MASTER'!$D$37:$D$39,MATCH(AE9,'SCORING MASTER'!$C$37:$C$39,0)),INDEX('SCORING MASTER'!$D$41:$D$43,MATCH(AF9,'SCORING MASTER'!$C$41:$C$43,0)),INDEX('SCORING MASTER'!$D$45:$D$47,MATCH(AG9,'SCORING MASTER'!$C$45:$C$47,0)),INDEX('SCORING MASTER'!$D$49:$D$52,MATCH(AH9,'SCORING MASTER'!$C$49:$C$52,0)),INDEX('SCORING MASTER'!$D$54:$D$57,MATCH(AI9,'SCORING MASTER'!$C$54:$C$57,0)))*20,0)) -> 93 | BI9: =IF(COUNTBLANK(AJ9:AP9)>0,"",ROUND(AVERAGE(INDEX('SCORING MASTER'!$D$59:$D$60,MATCH(AJ9,'SCORING MASTER'!$C$59:$C$60,0)),INDEX('SCORING MASTER'!$D$62:$D$63,MATCH(AK9,'SCORING MASTER'!$C$62:$C$63,0)),INDEX('SCORING MASTER'!$D$65:$D$66,MATCH(AL9,'SCORING MASTER'!$C$65:$C$66,0)),INDEX('SCORING MASTER'!$D$68:$D$69,MATCH(AM9,'SCORING MASTER'!$C$68:$C$69,0)),INDEX('SCORING MASTER'!$D$71:$D$72,MATCH(AN9,'SCORING MASTER'!$C$71:$C$72,0)),INDEX('SCORING MASTER'!$D$74:$D$75,MATCH(AO9,'SCORING MASTER'!$C$74:$C$75,0)),INDEX('SCORING MASTER'!$D$77:$D$78,MATCH(AP9,'SCORING MASTER'!$C$77:$C$78,0)))*20,0)) -> 100 | BJ9: =IF(COUNTBLANK(AU9:AZ9)>0,"",ROUND(AVERAGE(INDEX('SCORING MASTER'!$D$95:$D$96,MATCH(AU9,'SCORING MASTER'!$C$95:$C$96,0)),INDEX('SCORING MASTER'!$D$98:$D$99,MATCH(AV9,'SCORING MASTER'!$C$98:$C$99,0)),INDEX('SCORING MASTER'!$D$101:$D$102,MATCH(AW9,'SCORING MASTER'!$C$101:$C$102,0)),INDEX('SCORING MASTER'!$D$104:$D$105,MATCH(AX9,'SCORING MASTER'!$C$104:$C$105,0)),INDEX('SCORING MASTER'!$D$107:$D$108,MATCH(AY9,'SCORING MASTER'!$C$107:$C$108,0)),INDEX('SCORING MASTER'!$D$110:$D$111,MATCH(AZ9,'SCORING MASTER'!$C$110:$C$111,0)))*20,0)) -> 100 | BK9: =IF(COUNTBLANK(AQ9:AT9)>0,"",ROUND(AVERAGE(INDEX('SCORING MASTER'!$D$80:$D$82,MATCH(AQ9,'SCORING MASTER'!$C$80:$C$82,0)),INDEX('SCORING MASTER'!$D$84:$D$86,MATCH(AR9,'SCORING MASTER'!$C$84:$C$86,0)),INDEX('SCORING MASTER'!$D$88:$D$90,MATCH(AS9,'SCORING MASTER'!$C$88:$C$90,0)),INDEX('SCORING MASTER'!$D$92:$D$93,MATCH(AT9,'SCORING MASTER'!$C$92:$C$93,0)))*20,0)) -> 100 | BL9: =IF(COUNTBLANK(BA9:BE9)>0,"",ROUND(AVERAGE(INDEX('SCORING MASTER'!$D$113:$D$115,MATCH(BA9,'SCORING MASTER'!$C$113:$C$115,0)),INDEX('SCORING MASTER'!$D$117:$D$119,MATCH(BB9,'SCORING MASTER'!$C$117:$C$119,0)),INDEX('SCORING MASTER'!$D$121:$D$123,MATCH(BC9,'SCORING MASTER'!$C$121:$C$123,0)),INDEX('SCORING MASTER'!$D$125:$D$126,MATCH(BD9,'SCORING MASTER'!$C$125:$C$126,0)),INDEX('SCORING MASTER'!$D$128:$D$129,MATCH(BE9,'SCORING MASTER'!$C$128:$C$129,0)))*20,0)) -> 100 | BM9: =IF(OR(BF9="",BG9="",BH9="",BI9="",BJ9="",BK9="",BL9=""),"",ROUND(BF9*0.25+BG9*0.2+BH9*0.15+BI9*0.15+BJ9*0.1+BK9*0.1+BL9*0.05,0)) -> 82 | BN9: =IF(OR(BF9="",BG9=""),"",ROUND(BF9*0.5+BG9*0.5,0)) -> 64 | BO9: =IF(BN9="","",ROUND(MIN(100,MAX(0,(100-BN9)+IF(AL9="Yes",15,0)+IF(AM9="Yes",15,0)+IF(AND(U9<>"",U9<18.5),20,0))),0)) -> 36 | BP9: =IF(BM9="","",IF(BM9>=90,"Green - Healthy",IF(BM9>=75,"Light Green - Mild Watch",IF(BM9>=60,"Yellow - Mild Risk",IF(BM9>=40,"Orange - Moderate Risk","Red - High Risk"))))) -> Light Green - Mild Watch | BQ9: =IF(BM9="","",IF(OR(BM9<60,BO9>=60,AJ9="Yes"),"Yes","No")) -> No | BR9: =IF(BM9="","",IF(OR(BP9="Orange - Moderate Risk",BP9="Red - High Risk",BQ9="Yes"),"Yes","No")) -> No
A10: =IF(I10="","","STU"&TEXT(ROW()-3,"000000")) | S10: =IF(OR(Q10="",R10=""),"",ROUND(R10/((Q10/100)^2),1)) | T10: =IF(S10="","",IF(S10<18.5,"Underweight",IF(S10<25,"Normal",IF(S10<30,"Overweight","Obese")))) | BF10: =IF(T10="","",IF(T10="Normal",100,IF(T10="Overweight",65,IF(T10="Obese",50,IF(AND(U10<>"",U10<18.5),30,45))))) | BG10: =IF(COUNTBLANK(W10:AC10)>0,"",ROUND(AVERAGE(INDEX('SCORING MASTER'!$D$5:$D$7,MATCH(W10,'SCORING MASTER'!$C$5:$C$7,0)),INDEX('SCORING MASTER'!$D$9:$D$11,MATCH(X10,'SCORING MASTER'!$C$9:$C$11,0)),INDEX('SCORING MASTER'!$D$13:$D$15,MATCH(Y10,'SCORING MASTER'!$C$13:$C$15,0)),INDEX('SCORING MASTER'!$D$17:$D$19,MATCH(Z10,'SCORING MASTER'!$C$17:$C$19,0)),INDEX('SCORING MASTER'!$D$21:$D$23,MATCH(AA10,'SCORING MASTER'!$C$21:$C$23,0)),INDEX('SCORING MASTER'!$D$25:$D$27,MATCH(AB10,'SCORING MASTER'!$C$25:$C$27,0)),INDEX('SCORING MASTER'!$D$29:$D$31,MATCH(AC10,'SCORING MASTER'!$C$29:$C$31,0)))*20,0)) | BH10: =IF(COUNTBLANK(AD10:AI10)>0,"",ROUND(AVERAGE(INDEX('SCORING MASTER'!$D$33:$D$35,MATCH(AD10,'SCORING MASTER'!$C$33:$C$35,0)),INDEX('SCORING MASTER'!$D$37:$D$39,MATCH(AE10,'SCORING MASTER'!$C$37:$C$39,0)),INDEX('SCORING MASTER'!$D$41:$D$43,MATCH(AF10,'SCORING MASTER'!$C$41:$C$43,0)),INDEX('SCORING MASTER'!$D$45:$D$47,MATCH(AG10,'SCORING MASTER'!$C$45:$C$47,0)),INDEX('SCORING MASTER'!$D$49:$D$52,MATCH(AH10,'SCORING MASTER'!$C$49:$C$52,0)),INDEX('SCORING MASTER'!$D$54:$D$57,MATCH(AI10,'SCORING MASTER'!$C$54:$C$57,0)))*20,0)) | BI10: =IF(COUNTBLANK(AJ10:AP10)>0,"",ROUND(AVERAGE(INDEX('SCORING MASTER'!$D$59:$D$60,MATCH(AJ10,'SCORING MASTER'!$C$59:$C$60,0)),INDEX('SCORING MASTER'!$D$62:$D$63,MATCH(AK10,'SCORING MASTER'!$C$62:$C$63,0)),INDEX('SCORING MASTER'!$D$65:$D$66,MATCH(AL10,'SCORING MASTER'!$C$65:$C$66,0)),INDEX('SCORING MASTER'!$D$68:$D$69,MATCH(AM10,'SCORING MASTER'!$C$68:$C$69,0)),INDEX('SCORING MASTER'!$D$71:$D$72,MATCH(AN10,'SCORING MASTER'!$C$71:$C$72,0)),INDEX('SCORING MASTER'!$D$74:$D$75,MATCH(AO10,'SCORING MASTER'!$C$74:$C$75,0)),INDEX('SCORING MASTER'!$D$77:$D$78,MATCH(AP10,'SCORING MASTER'!$C$77:$C$78,0)))*20,0)) | BJ10: =IF(COUNTBLANK(AU10:AZ10)>0,"",ROUND(AVERAGE(INDEX('SCORING MASTER'!$D$95:$D$96,MATCH(AU10,'SCORING MASTER'!$C$95:$C$96,0)),INDEX('SCORING MASTER'!$D$98:$D$99,MATCH(AV10,'SCORING MASTER'!$C$98:$C$99,0)),INDEX('SCORING MASTER'!$D$101:$D$102,MATCH(AW10,'SCORING MASTER'!$C$101:$C$102,0)),INDEX('SCORING MASTER'!$D$104:$D$105,MATCH(AX10,'SCORING MASTER'!$C$104:$C$105,0)),INDEX('SCORING MASTER'!$D$107:$D$108,MATCH(AY10,'SCORING MASTER'!$C$107:$C$108,0)),INDEX('SCORING MASTER'!$D$110:$D$111,MATCH(AZ10,'SCORING MASTER'!$C$110:$C$111,0)))*20,0)) | BK10: =IF(COUNTBLANK(AQ10:AT10)>0,"",ROUND(AVERAGE(INDEX('SCORING MASTER'!$D$80:$D$82,MATCH(AQ10,'SCORING MASTER'!$C$80:$C$82,0)),INDEX('SCORING MASTER'!$D$84:$D$86,MATCH(AR10,'SCORING MASTER'!$C$84:$C$86,0)),INDEX('SCORING MASTER'!$D$88:$D$90,MATCH(AS10,'SCORING MASTER'!$C$88:$C$90,0)),INDEX('SCORING MASTER'!$D$92:$D$93,MATCH(AT10,'SCORING MASTER'!$C$92:$C$93,0)))*20,0)) | BL10: =IF(COUNTBLANK(BA10:BE10)>0,"",ROUND(AVERAGE(INDEX('SCORING MASTER'!$D$113:$D$115,MATCH(BA10,'SCORING MASTER'!$C$113:$C$115,0)),INDEX('SCORING MASTER'!$D$117:$D$119,MATCH(BB10,'SCORING MASTER'!$C$117:$C$119,0)),INDEX('SCORING MASTER'!$D$121:$D$123,MATCH(BC10,'SCORING MASTER'!$C$121:$C$123,0)),INDEX('SCORING MASTER'!$D$125:$D$126,MATCH(BD10,'SCORING MASTER'!$C$125:$C$126,0)),INDEX('SCORING MASTER'!$D$128:$D$129,MATCH(BE10,'SCORING MASTER'!$C$128:$C$129,0)))*20,0)) | BM10: =IF(OR(BF10="",BG10="",BH10="",BI10="",BJ10="",BK10="",BL10=""),"",ROUND(BF10*0.25+BG10*0.2+BH10*0.15+BI10*0.15+BJ10*0.1+BK10*0.1+BL10*0.05,0)) | BN10: =IF(OR(BF10="",BG10=""),"",ROUND(BF10*0.5+BG10*0.5,0)) | BO10: =IF(BN10="","",ROUND(MIN(100,MAX(0,(100-BN10)+IF(AL10="Yes",15,0)+IF(AM10="Yes",15,0)+IF(AND(U10<>"",U10<18.5),20,0))),0)) | BP10: =IF(BM10="","",IF(BM10>=90,"Green - Healthy",IF(BM10>=75,"Light Green - Mild Watch",IF(BM10>=60,"Yellow - Mild Risk",IF(BM10>=40,"Orange - Moderate Risk","Red - High Risk"))))) | BQ10: =IF(BM10="","",IF(OR(BM10<60,BO10>=60,AJ10="Yes"),"Yes","No")) | BR10: =IF(BM10="","",IF(OR(BP10="Orange - Moderate Risk",BP10="Red - High Risk",BQ10="Yes"),"Yes","No"))
A11: =IF(I11="","","STU"&TEXT(ROW()-3,"000000")) | S11: =IF(OR(Q11="",R11=""),"",ROUND(R11/((Q11/100)^2),1)) | T11: =IF(S11="","",IF(S11<18.5,"Underweight",IF(S11<25,"Normal",IF(S11<30,"Overweight","Obese")))) | BF11: =IF(T11="","",IF(T11="Normal",100,IF(T11="Overweight",65,IF(T11="Obese",50,IF(AND(U11<>"",U11<18.5),30,45))))) | BG11: =IF(COUNTBLANK(W11:AC11)>0,"",ROUND(AVERAGE(INDEX('SCORING MASTER'!$D$5:$D$7,MATCH(W11,'SCORING MASTER'!$C$5:$C$7,0)),INDEX('SCORING MASTER'!$D$9:$D$11,MATCH(X11,'SCORING MASTER'!$C$9:$C$11,0)),INDEX('SCORING MASTER'!$D$13:$D$15,MATCH(Y11,'SCORING MASTER'!$C$13:$C$15,0)),INDEX('SCORING MASTER'!$D$17:$D$19,MATCH(Z11,'SCORING MASTER'!$C$17:$C$19,0)),INDEX('SCORING MASTER'!$D$21:$D$23,MATCH(AA11,'SCORING MASTER'!$C$21:$C$23,0)),INDEX('SCORING MASTER'!$D$25:$D$27,MATCH(AB11,'SCORING MASTER'!$C$25:$C$27,0)),INDEX('SCORING MASTER'!$D$29:$D$31,MATCH(AC11,'SCORING MASTER'!$C$29:$C$31,0)))*20,0)) | BH11: =IF(COUNTBLANK(AD11:AI11)>0,"",ROUND(AVERAGE(INDEX('SCORING MASTER'!$D$33:$D$35,MATCH(AD11,'SCORING MASTER'!$C$33:$C$35,0)),INDEX('SCORING MASTER'!$D$37:$D$39,MATCH(AE11,'SCORING MASTER'!$C$37:$C$39,0)),INDEX('SCORING MASTER'!$D$41:$D$43,MATCH(AF11,'SCORING MASTER'!$C$41:$C$43,0)),INDEX('SCORING MASTER'!$D$45:$D$47,MATCH(AG11,'SCORING MASTER'!$C$45:$C$47,0)),INDEX('SCORING MASTER'!$D$49:$D$52,MATCH(AH11,'SCORING MASTER'!$C$49:$C$52,0)),INDEX('SCORING MASTER'!$D$54:$D$57,MATCH(AI11,'SCORING MASTER'!$C$54:$C$57,0)))*20,0)) | BI11: =IF(COUNTBLANK(AJ11:AP11)>0,"",ROUND(AVERAGE(INDEX('SCORING MASTER'!$D$59:$D$60,MATCH(AJ11,'SCORING MASTER'!$C$59:$C$60,0)),INDEX('SCORING MASTER'!$D$62:$D$63,MATCH(AK11,'SCORING MASTER'!$C$62:$C$63,0)),INDEX('SCORING MASTER'!$D$65:$D$66,MATCH(AL11,'SCORING MASTER'!$C$65:$C$66,0)),INDEX('SCORING MASTER'!$D$68:$D$69,MATCH(AM11,'SCORING MASTER'!$C$68:$C$69,0)),INDEX('SCORING MASTER'!$D$71:$D$72,MATCH(AN11,'SCORING MASTER'!$C$71:$C$72,0)),INDEX('SCORING MASTER'!$D$74:$D$75,MATCH(AO11,'SCORING MASTER'!$C$74:$C$75,0)),INDEX('SCORING MASTER'!$D$77:$D$78,MATCH(AP11,'SCORING MASTER'!$C$77:$C$78,0)))*20,0)) | BJ11: =IF(COUNTBLANK(AU11:AZ11)>0,"",ROUND(AVERAGE(INDEX('SCORING MASTER'!$D$95:$D$96,MATCH(AU11,'SCORING MASTER'!$C$95:$C$96,0)),INDEX('SCORING MASTER'!$D$98:$D$99,MATCH(AV11,'SCORING MASTER'!$C$98:$C$99,0)),INDEX('SCORING MASTER'!$D$101:$D$102,MATCH(AW11,'SCORING MASTER'!$C$101:$C$102,0)),INDEX('SCORING MASTER'!$D$104:$D$105,MATCH(AX11,'SCORING MASTER'!$C$104:$C$105,0)),INDEX('SCORING MASTER'!$D$107:$D$108,MATCH(AY11,'SCORING MASTER'!$C$107:$C$108,0)),INDEX('SCORING MASTER'!$D$110:$D$111,MATCH(AZ11,'SCORING MASTER'!$C$110:$C$111,0)))*20,0)) | BK11: =IF(COUNTBLANK(AQ11:AT11)>0,"",ROUND(AVERAGE(INDEX('SCORING MASTER'!$D$80:$D$82,MATCH(AQ11,'SCORING MASTER'!$C$80:$C$82,0)),INDEX('SCORING MASTER'!$D$84:$D$86,MATCH(AR11,'SCORING MASTER'!$C$84:$C$86,0)),INDEX('SCORING MASTER'!$D$88:$D$90,MATCH(AS11,'SCORING MASTER'!$C$88:$C$90,0)),INDEX('SCORING MASTER'!$D$92:$D$93,MATCH(AT11,'SCORING MASTER'!$C$92:$C$93,0)))*20,0)) | BL11: =IF(COUNTBLANK(BA11:BE11)>0,"",ROUND(AVERAGE(INDEX('SCORING MASTER'!$D$113:$D$115,MATCH(BA11,'SCORING MASTER'!$C$113:$C$115,0)),INDEX('SCORING MASTER'!$D$117:$D$119,MATCH(BB11,'SCORING MASTER'!$C$117:$C$119,0)),INDEX('SCORING MASTER'!$D$121:$D$123,MATCH(BC11,'SCORING MASTER'!$C$121:$C$123,0)),INDEX('SCORING MASTER'!$D$125:$D$126,MATCH(BD11,'SCORING MASTER'!$C$125:$C$126,0)),INDEX('SCORING MASTER'!$D$128:$D$129,MATCH(BE11,'SCORING MASTER'!$C$128:$C$129,0)))*20,0)) | BM11: =IF(OR(BF11="",BG11="",BH11="",BI11="",BJ11="",BK11="",BL11=""),"",ROUND(BF11*0.25+BG11*0.2+BH11*0.15+BI11*0.15+BJ11*0.1+BK11*0.1+BL11*0.05,0)) | BN11: =IF(OR(BF11="",BG11=""),"",ROUND(BF11*0.5+BG11*0.5,0)) | BO11: =IF(BN11="","",ROUND(MIN(100,MAX(0,(100-BN11)+IF(AL11="Yes",15,0)+IF(AM11="Yes",15,0)+IF(AND(U11<>"",U11<18.5),20,0))),0)) | BP11: =IF(BM11="","",IF(BM11>=90,"Green - Healthy",IF(BM11>=75,"Light Green - Mild Watch",IF(BM11>=60,"Yellow - Mild Risk",IF(BM11>=40,"Orange - Moderate Risk","Red - High Risk"))))) | BQ11: =IF(BM11="","",IF(OR(BM11<60,BO11>=60,AJ11="Yes"),"Yes","No")) | BR11: =IF(BM11="","",IF(OR(BP11="Orange - Moderate Risk",BP11="Red - High Risk",BQ11="Yes"),"Yes","No"))
A12: =IF(I12="","","STU"&TEXT(ROW()-3,"000000")) | S12: =IF(OR(Q12="",R12=""),"",ROUND(R12/((Q12/100)^2),1)) | T12: =IF(S12="","",IF(S12<18.5,"Underweight",IF(S12<25,"Normal",IF(S12<30,"Overweight","Obese")))) | BF12: =IF(T12="","",IF(T12="Normal",100,IF(T12="Overweight",65,IF(T12="Obese",50,IF(AND(U12<>"",U12<18.5),30,45))))) | BG12: =IF(COUNTBLANK(W12:AC12)>0,"",ROUND(AVERAGE(INDEX('SCORING MASTER'!$D$5:$D$7,MATCH(W12,'SCORING MASTER'!$C$5:$C$7,0)),INDEX('SCORING MASTER'!$D$9:$D$11,MATCH(X12,'SCORING MASTER'!$C$9:$C$11,0)),INDEX('SCORING MASTER'!$D$13:$D$15,MATCH(Y12,'SCORING MASTER'!$C$13:$C$15,0)),INDEX('SCORING MASTER'!$D$17:$D$19,MATCH(Z12,'SCORING MASTER'!$C$17:$C$19,0)),INDEX('SCORING MASTER'!$D$21:$D$23,MATCH(AA12,'SCORING MASTER'!$C$21:$C$23,0)),INDEX('SCORING MASTER'!$D$25:$D$27,MATCH(AB12,'SCORING MASTER'!$C$25:$C$27,0)),INDEX('SCORING MASTER'!$D$29:$D$31,MATCH(AC12,'SCORING MASTER'!$C$29:$C$31,0)))*20,0)) | BH12: =IF(COUNTBLANK(AD12:AI12)>0,"",ROUND(AVERAGE(INDEX('SCORING MASTER'!$D$33:$D$35,MATCH(AD12,'SCORING MASTER'!$C$33:$C$35,0)),INDEX('SCORING MASTER'!$D$37:$D$39,MATCH(AE12,'SCORING MASTER'!$C$37:$C$39,0)),INDEX('SCORING MASTER'!$D$41:$D$43,MATCH(AF12,'SCORING MASTER'!$C$41:$C$43,0)),INDEX('SCORING MASTER'!$D$45:$D$47,MATCH(AG12,'SCORING MASTER'!$C$45:$C$47,0)),INDEX('SCORING MASTER'!$D$49:$D$52,MATCH(AH12,'SCORING MASTER'!$C$49:$C$52,0)),INDEX('SCORING MASTER'!$D$54:$D$57,MATCH(AI12,'SCORING MASTER'!$C$54:$C$57,0)))*20,0)) | BI12: =IF(COUNTBLANK(AJ12:AP12)>0,"",ROUND(AVERAGE(INDEX('SCORING MASTER'!$D$59:$D$60,MATCH(AJ12,'SCORING MASTER'!$C$59:$C$60,0)),INDEX('SCORING MASTER'!$D$62:$D$63,MATCH(AK12,'SCORING MASTER'!$C$62:$C$63,0)),INDEX('SCORING MASTER'!$D$65:$D$66,MATCH(AL12,'SCORING MASTER'!$C$65:$C$66,0)),INDEX('SCORING MASTER'!$D$68:$D$69,MATCH(AM12,'SCORING MASTER'!$C$68:$C$69,0)),INDEX('SCORING MASTER'!$D$71:$D$72,MATCH(AN12,'SCORING MASTER'!$C$71:$C$72,0)),INDEX('SCORING MASTER'!$D$74:$D$75,MATCH(AO12,'SCORING MASTER'!$C$74:$C$75,0)),INDEX('SCORING MASTER'!$D$77:$D$78,MATCH(AP12,'SCORING MASTER'!$C$77:$C$78,0)))*20,0)) | BJ12: =IF(COUNTBLANK(AU12:AZ12)>0,"",ROUND(AVERAGE(INDEX('SCORING MASTER'!$D$95:$D$96,MATCH(AU12,'SCORING MASTER'!$C$95:$C$96,0)),INDEX('SCORING MASTER'!$D$98:$D$99,MATCH(AV12,'SCORING MASTER'!$C$98:$C$99,0)),INDEX('SCORING MASTER'!$D$101:$D$102,MATCH(AW12,'SCORING MASTER'!$C$101:$C$102,0)),INDEX('SCORING MASTER'!$D$104:$D$105,MATCH(AX12,'SCORING MASTER'!$C$104:$C$105,0)),INDEX('SCORING MASTER'!$D$107:$D$108,MATCH(AY12,'SCORING MASTER'!$C$107:$C$108,0)),INDEX('SCORING MASTER'!$D$110:$D$111,MATCH(AZ12,'SCORING MASTER'!$C$110:$C$111,0)))*20,0)) | BK12: =IF(COUNTBLANK(AQ12:AT12)>0,"",ROUND(AVERAGE(INDEX('SCORING MASTER'!$D$80:$D$82,MATCH(AQ12,'SCORING MASTER'!$C$80:$C$82,0)),INDEX('SCORING MASTER'!$D$84:$D$86,MATCH(AR12,'SCORING MASTER'!$C$84:$C$86,0)),INDEX('SCORING MASTER'!$D$88:$D$90,MATCH(AS12,'SCORING MASTER'!$C$88:$C$90,0)),INDEX('SCORING MASTER'!$D$92:$D$93,MATCH(AT12,'SCORING MASTER'!$C$92:$C$93,0)))*20,0)) | BL12: =IF(COUNTBLANK(BA12:BE12)>0,"",ROUND(AVERAGE(INDEX('SCORING MASTER'!$D$113:$D$115,MATCH(BA12,'SCORING MASTER'!$C$113:$C$115,0)),INDEX('SCORING MASTER'!$D$117:$D$119,MATCH(BB12,'SCORING MASTER'!$C$117:$C$119,0)),INDEX('SCORING MASTER'!$D$121:$D$123,MATCH(BC12,'SCORING MASTER'!$C$121:$C$123,0)),INDEX('SCORING MASTER'!$D$125:$D$126,MATCH(BD12,'SCORING MASTER'!$C$125:$C$126,0)),INDEX('SCORING MASTER'!$D$128:$D$129,MATCH(BE12,'SCORING MASTER'!$C$128:$C$129,0)))*20,0)) | BM12: =IF(OR(BF12="",BG12="",BH12="",BI12="",BJ12="",BK12="",BL12=""),"",ROUND(BF12*0.25+BG12*0.2+BH12*0.15+BI12*0.15+BJ12*0.1+BK12*0.1+BL12*0.05,0)) | BN12: =IF(OR(BF12="",BG12=""),"",ROUND(BF12*0.5+BG12*0.5,0)) | BO12: =IF(BN12="","",ROUND(MIN(100,MAX(0,(100-BN12)+IF(AL12="Yes",15,0)+IF(AM12="Yes",15,0)+IF(AND(U12<>"",U12<18.5),20,0))),0)) | BP12: =IF(BM12="","",IF(BM12>=90,"Green - Healthy",IF(BM12>=75,"Light Green - Mild Watch",IF(BM12>=60,"Yellow - Mild Risk",IF(BM12>=40,"Orange - Moderate Risk","Red - High Risk"))))) | BQ12: =IF(BM12="","",IF(OR(BM12<60,BO12>=60,AJ12="Yes"),"Yes","No")) | BR12: =IF(BM12="","",IF(OR(BP12="Orange - Moderate Risk",BP12="Red - High Risk",BQ12="Yes"),"Yes","No"))
A13: =IF(I13="","","STU"&TEXT(ROW()-3,"000000")) | S13: =IF(OR(Q13="",R13=""),"",ROUND(R13/((Q13/100)^2),1)) | T13: =IF(S13="","",IF(S13<18.5,"Underweight",IF(S13<25,"Normal",IF(S13<30,"Overweight","Obese")))) | BF13: =IF(T13="","",IF(T13="Normal",100,IF(T13="Overweight",65,IF(T13="Obese",50,IF(AND(U13<>"",U13<18.5),30,45))))) | BG13: =IF(COUNTBLANK(W13:AC13)>0,"",ROUND(AVERAGE(INDEX('SCORING MASTER'!$D$5:$D$7,MATCH(W13,'SCORING MASTER'!$C$5:$C$7,0)),INDEX('SCORING MASTER'!$D$9:$D$11,MATCH(X13,'SCORING MASTER'!$C$9:$C$11,0)),INDEX('SCORING MASTER'!$D$13:$D$15,MATCH(Y13,'SCORING MASTER'!$C$13:$C$15,0)),INDEX('SCORING MASTER'!$D$17:$D$19,MATCH(Z13,'SCORING MASTER'!$C$17:$C$19,0)),INDEX('SCORING MASTER'!$D$21:$D$23,MATCH(AA13,'SCORING MASTER'!$C$21:$C$23,0)),INDEX('SCORING MASTER'!$D$25:$D$27,MATCH(AB13,'SCORING MASTER'!$C$25:$C$27,0)),INDEX('SCORING MASTER'!$D$29:$D$31,MATCH(AC13,'SCORING MASTER'!$C$29:$C$31,0)))*20,0)) | BH13: =IF(COUNTBLANK(AD13:AI13)>0,"",ROUND(AVERAGE(INDEX('SCORING MASTER'!$D$33:$D$35,MATCH(AD13,'SCORING MASTER'!$C$33:$C$35,0)),INDEX('SCORING MASTER'!$D$37:$D$39,MATCH(AE13,'SCORING MASTER'!$C$37:$C$39,0)),INDEX('SCORING MASTER'!$D$41:$D$43,MATCH(AF13,'SCORING MASTER'!$C$41:$C$43,0)),INDEX('SCORING MASTER'!$D$45:$D$47,MATCH(AG13,'SCORING MASTER'!$C$45:$C$47,0)),INDEX('SCORING MASTER'!$D$49:$D$52,MATCH(AH13,'SCORING MASTER'!$C$49:$C$52,0)),INDEX('SCORING MASTER'!$D$54:$D$57,MATCH(AI13,'SCORING MASTER'!$C$54:$C$57,0)))*20,0)) | BI13: =IF(COUNTBLANK(AJ13:AP13)>0,"",ROUND(AVERAGE(INDEX('SCORING MASTER'!$D$59:$D$60,MATCH(AJ13,'SCORING MASTER'!$C$59:$C$60,0)),INDEX('SCORING MASTER'!$D$62:$D$63,MATCH(AK13,'SCORING MASTER'!$C$62:$C$63,0)),INDEX('SCORING MASTER'!$D$65:$D$66,MATCH(AL13,'SCORING MASTER'!$C$65:$C$66,0)),INDEX('SCORING MASTER'!$D$68:$D$69,MATCH(AM13,'SCORING MASTER'!$C$68:$C$69,0)),INDEX('SCORING MASTER'!$D$71:$D$72,MATCH(AN13,'SCORING MASTER'!$C$71:$C$72,0)),INDEX('SCORING MASTER'!$D$74:$D$75,MATCH(AO13,'SCORING MASTER'!$C$74:$C$75,0)),INDEX('SCORING MASTER'!$D$77:$D$78,MATCH(AP13,'SCORING MASTER'!$C$77:$C$78,0)))*20,0)) | BJ13: =IF(COUNTBLANK(AU13:AZ13)>0,"",ROUND(AVERAGE(INDEX('SCORING MASTER'!$D$95:$D$96,MATCH(AU13,'SCORING MASTER'!$C$95:$C$96,0)),INDEX('SCORING MASTER'!$D$98:$D$99,MATCH(AV13,'SCORING MASTER'!$C$98:$C$99,0)),INDEX('SCORING MASTER'!$D$101:$D$102,MATCH(AW13,'SCORING MASTER'!$C$101:$C$102,0)),INDEX('SCORING MASTER'!$D$104:$D$105,MATCH(AX13,'SCORING MASTER'!$C$104:$C$105,0)),INDEX('SCORING MASTER'!$D$107:$D$108,MATCH(AY13,'SCORING MASTER'!$C$107:$C$108,0)),INDEX('SCORING MASTER'!$D$110:$D$111,MATCH(AZ13,'SCORING MASTER'!$C$110:$C$111,0)))*20,0)) | BK13: =IF(COUNTBLANK(AQ13:AT13)>0,"",ROUND(AVERAGE(INDEX('SCORING MASTER'!$D$80:$D$82,MATCH(AQ13,'SCORING MASTER'!$C$80:$C$82,0)),INDEX('SCORING MASTER'!$D$84:$D$86,MATCH(AR13,'SCORING MASTER'!$C$84:$C$86,0)),INDEX('SCORING MASTER'!$D$88:$D$90,MATCH(AS13,'SCORING MASTER'!$C$88:$C$90,0)),INDEX('SCORING MASTER'!$D$92:$D$93,MATCH(AT13,'SCORING MASTER'!$C$92:$C$93,0)))*20,0)) | BL13: =IF(COUNTBLANK(BA13:BE13)>0,"",ROUND(AVERAGE(INDEX('SCORING MASTER'!$D$113:$D$115,MATCH(BA13,'SCORING MASTER'!$C$113:$C$115,0)),INDEX('SCORING MASTER'!$D$117:$D$119,MATCH(BB13,'SCORING MASTER'!$C$117:$C$119,0)),INDEX('SCORING MASTER'!$D$121:$D$123,MATCH(BC13,'SCORING MASTER'!$C$121:$C$123,0)),INDEX('SCORING MASTER'!$D$125:$D$126,MATCH(BD13,'SCORING MASTER'!$C$125:$C$126,0)),INDEX('SCORING MASTER'!$D$128:$D$129,MATCH(BE13,'SCORING MASTER'!$C$128:$C$129,0)))*20,0)) | BM13: =IF(OR(BF13="",BG13="",BH13="",BI13="",BJ13="",BK13="",BL13=""),"",ROUND(BF13*0.25+BG13*0.2+BH13*0.15+BI13*0.15+BJ13*0.1+BK13*0.1+BL13*0.05,0)) | BN13: =IF(OR(BF13="",BG13=""),"",ROUND(BF13*0.5+BG13*0.5,0)) | BO13: =IF(BN13="","",ROUND(MIN(100,MAX(0,(100-BN13)+IF(AL13="Yes",15,0)+IF(AM13="Yes",15,0)+IF(AND(U13<>"",U13<18.5),20,0))),0)) | BP13: =IF(BM13="","",IF(BM13>=90,"Green - Healthy",IF(BM13>=75,"Light Green - Mild Watch",IF(BM13>=60,"Yellow - Mild Risk",IF(BM13>=40,"Orange - Moderate Risk","Red - High Risk"))))) | BQ13: =IF(BM13="","",IF(OR(BM13<60,BO13>=60,AJ13="Yes"),"Yes","No")) | BR13: =IF(BM13="","",IF(OR(BP13="Orange - Moderate Risk",BP13="Red - High Risk",BQ13="Yes"),"Yes","No"))
A14: =IF(I14="","","STU"&TEXT(ROW()-3,"000000")) | S14: =IF(OR(Q14="",R14=""),"",ROUND(R14/((Q14/100)^2),1)) | T14: =IF(S14="","",IF(S14<18.5,"Underweight",IF(S14<25,"Normal",IF(S14<30,"Overweight","Obese")))) | BF14: =IF(T14="","",IF(T14="Normal",100,IF(T14="Overweight",65,IF(T14="Obese",50,IF(AND(U14<>"",U14<18.5),30,45))))) | BG14: =IF(COUNTBLANK(W14:AC14)>0,"",ROUND(AVERAGE(INDEX('SCORING MASTER'!$D$5:$D$7,MATCH(W14,'SCORING MASTER'!$C$5:$C$7,0)),INDEX('SCORING MASTER'!$D$9:$D$11,MATCH(X14,'SCORING MASTER'!$C$9:$C$11,0)),INDEX('SCORING MASTER'!$D$13:$D$15,MATCH(Y14,'SCORING MASTER'!$C$13:$C$15,0)),INDEX('SCORING MASTER'!$D$17:$D$19,MATCH(Z14,'SCORING MASTER'!$C$17:$C$19,0)),INDEX('SCORING MASTER'!$D$21:$D$23,MATCH(AA14,'SCORING MASTER'!$C$21:$C$23,0)),INDEX('SCORING MASTER'!$D$25:$D$27,MATCH(AB14,'SCORING MASTER'!$C$25:$C$27,0)),INDEX('SCORING MASTER'!$D$29:$D$31,MATCH(AC14,'SCORING MASTER'!$C$29:$C$31,0)))*20,0)) | BH14: =IF(COUNTBLANK(AD14:AI14)>0,"",ROUND(AVERAGE(INDEX('SCORING MASTER'!$D$33:$D$35,MATCH(AD14,'SCORING MASTER'!$C$33:$C$35,0)),INDEX('SCORING MASTER'!$D$37:$D$39,MATCH(AE14,'SCORING MASTER'!$C$37:$C$39,0)),INDEX('SCORING MASTER'!$D$41:$D$43,MATCH(AF14,'SCORING MASTER'!$C$41:$C$43,0)),INDEX('SCORING MASTER'!$D$45:$D$47,MATCH(AG14,'SCORING MASTER'!$C$45:$C$47,0)),INDEX('SCORING MASTER'!$D$49:$D$52,MATCH(AH14,'SCORING MASTER'!$C$49:$C$52,0)),INDEX('SCORING MASTER'!$D$54:$D$57,MATCH(AI14,'SCORING MASTER'!$C$54:$C$57,0)))*20,0)) | BI14: =IF(COUNTBLANK(AJ14:AP14)>0,"",ROUND(AVERAGE(INDEX('SCORING MASTER'!$D$59:$D$60,MATCH(AJ14,'SCORING MASTER'!$C$59:$C$60,0)),INDEX('SCORING MASTER'!$D$62:$D$63,MATCH(AK14,'SCORING MASTER'!$C$62:$C$63,0)),INDEX('SCORING MASTER'!$D$65:$D$66,MATCH(AL14,'SCORING MASTER'!$C$65:$C$66,0)),INDEX('SCORING MASTER'!$D$68:$D$69,MATCH(AM14,'SCORING MASTER'!$C$68:$C$69,0)),INDEX('SCORING MASTER'!$D$71:$D$72,MATCH(AN14,'SCORING MASTER'!$C$71:$C$72,0)),INDEX('SCORING MASTER'!$D$74:$D$75,MATCH(AO14,'SCORING MASTER'!$C$74:$C$75,0)),INDEX('SCORING MASTER'!$D$77:$D$78,MATCH(AP14,'SCORING MASTER'!$C$77:$C$78,0)))*20,0)) | BJ14: =IF(COUNTBLANK(AU14:AZ14)>0,"",ROUND(AVERAGE(INDEX('SCORING MASTER'!$D$95:$D$96,MATCH(AU14,'SCORING MASTER'!$C$95:$C$96,0)),INDEX('SCORING MASTER'!$D$98:$D$99,MATCH(AV14,'SCORING MASTER'!$C$98:$C$99,0)),INDEX('SCORING MASTER'!$D$101:$D$102,MATCH(AW14,'SCORING MASTER'!$C$101:$C$102,0)),INDEX('SCORING MASTER'!$D$104:$D$105,MATCH(AX14,'SCORING MASTER'!$C$104:$C$105,0)),INDEX('SCORING MASTER'!$D$107:$D$108,MATCH(AY14,'SCORING MASTER'!$C$107:$C$108,0)),INDEX('SCORING MASTER'!$D$110:$D$111,MATCH(AZ14,'SCORING MASTER'!$C$110:$C$111,0)))*20,0)) | BK14: =IF(COUNTBLANK(AQ14:AT14)>0,"",ROUND(AVERAGE(INDEX('SCORING MASTER'!$D$80:$D$82,MATCH(AQ14,'SCORING MASTER'!$C$80:$C$82,0)),INDEX('SCORING MASTER'!$D$84:$D$86,MATCH(AR14,'SCORING MASTER'!$C$84:$C$86,0)),INDEX('SCORING MASTER'!$D$88:$D$90,MATCH(AS14,'SCORING MASTER'!$C$88:$C$90,0)),INDEX('SCORING MASTER'!$D$92:$D$93,MATCH(AT14,'SCORING MASTER'!$C$92:$C$93,0)))*20,0)) | BL14: =IF(COUNTBLANK(BA14:BE14)>0,"",ROUND(AVERAGE(INDEX('SCORING MASTER'!$D$113:$D$115,MATCH(BA14,'SCORING MASTER'!$C$113:$C$115,0)),INDEX('SCORING MASTER'!$D$117:$D$119,MATCH(BB14,'SCORING MASTER'!$C$117:$C$119,0)),INDEX('SCORING MASTER'!$D$121:$D$123,MATCH(BC14,'SCORING MASTER'!$C$121:$C$123,0)),INDEX('SCORING MASTER'!$D$125:$D$126,MATCH(BD14,'SCORING MASTER'!$C$125:$C$126,0)),INDEX('SCORING MASTER'!$D$128:$D$129,MATCH(BE14,'SCORING MASTER'!$C$128:$C$129,0)))*20,0)) | BM14: =IF(OR(BF14="",BG14="",BH14="",BI14="",BJ14="",BK14="",BL14=""),"",ROUND(BF14*0.25+BG14*0.2+BH14*0.15+BI14*0.15+BJ14*0.1+BK14*0.1+BL14*0.05,0)) | BN14: =IF(OR(BF14="",BG14=""),"",ROUND(BF14*0.5+BG14*0.5,0)) | BO14: =IF(BN14="","",ROUND(MIN(100,MAX(0,(100-BN14)+IF(AL14="Yes",15,0)+IF(AM14="Yes",15,0)+IF(AND(U14<>"",U14<18.5),20,0))),0)) | BP14: =IF(BM14="","",IF(BM14>=90,"Green - Healthy",IF(BM14>=75,"Light Green - Mild Watch",IF(BM14>=60,"Yellow - Mild Risk",IF(BM14>=40,"Orange - Moderate Risk","Red - High Risk"))))) | BQ14: =IF(BM14="","",IF(OR(BM14<60,BO14>=60,AJ14="Yes"),"Yes","No")) | BR14: =IF(BM14="","",IF(OR(BP14="Orange - Moderate Risk",BP14="Red - High Risk",BQ14="Yes"),"Yes","No"))
A15: =IF(I15="","","STU"&TEXT(ROW()-3,"000000")) | S15: =IF(OR(Q15="",R15=""),"",ROUND(R15/((Q15/100)^2),1)) | T15: =IF(S15="","",IF(S15<18.5,"Underweight",IF(S15<25,"Normal",IF(S15<30,"Overweight","Obese")))) | BF15: =IF(T15="","",IF(T15="Normal",100,IF(T15="Overweight",65,IF(T15="Obese",50,IF(AND(U15<>"",U15<18.5),30,45))))) | BG15: =IF(COUNTBLANK(W15:AC15)>0,"",ROUND(AVERAGE(INDEX('SCORING MASTER'!$D$5:$D$7,MATCH(W15,'SCORING MASTER'!$C$5:$C$7,0)),INDEX('SCORING MASTER'!$D$9:$D$11,MATCH(X15,'SCORING MASTER'!$C$9:$C$11,0)),INDEX('SCORING MASTER'!$D$13:$D$15,MATCH(Y15,'SCORING MASTER'!$C$13:$C$15,0)),INDEX('SCORING MASTER'!$D$17:$D$19,MATCH(Z15,'SCORING MASTER'!$C$17:$C$19,0)),INDEX('SCORING MASTER'!$D$21:$D$23,MATCH(AA15,'SCORING MASTER'!$C$21:$C$23,0)),INDEX('SCORING MASTER'!$D$25:$D$27,MATCH(AB15,'SCORING MASTER'!$C$25:$C$27,0)),INDEX('SCORING MASTER'!$D$29:$D$31,MATCH(AC15,'SCORING MASTER'!$C$29:$C$31,0)))*20,0)) | BH15: =IF(COUNTBLANK(AD15:AI15)>0,"",ROUND(AVERAGE(INDEX('SCORING MASTER'!$D$33:$D$35,MATCH(AD15,'SCORING MASTER'!$C$33:$C$35,0)),INDEX('SCORING MASTER'!$D$37:$D$39,MATCH(AE15,'SCORING MASTER'!$C$37:$C$39,0)),INDEX('SCORING MASTER'!$D$41:$D$43,MATCH(AF15,'SCORING MASTER'!$C$41:$C$43,0)),INDEX('SCORING MASTER'!$D$45:$D$47,MATCH(AG15,'SCORING MASTER'!$C$45:$C$47,0)),INDEX('SCORING MASTER'!$D$49:$D$52,MATCH(AH15,'SCORING MASTER'!$C$49:$C$52,0)),INDEX('SCORING MASTER'!$D$54:$D$57,MATCH(AI15,'SCORING MASTER'!$C$54:$C$57,0)))*20,0)) | BI15: =IF(COUNTBLANK(AJ15:AP15)>0,"",ROUND(AVERAGE(INDEX('SCORING MASTER'!$D$59:$D$60,MATCH(AJ15,'SCORING MASTER'!$C$59:$C$60,0)),INDEX('SCORING MASTER'!$D$62:$D$63,MATCH(AK15,'SCORING MASTER'!$C$62:$C$63,0)),INDEX('SCORING MASTER'!$D$65:$D$66,MATCH(AL15,'SCORING MASTER'!$C$65:$C$66,0)),INDEX('SCORING MASTER'!$D$68:$D$69,MATCH(AM15,'SCORING MASTER'!$C$68:$C$69,0)),INDEX('SCORING MASTER'!$D$71:$D$72,MATCH(AN15,'SCORING MASTER'!$C$71:$C$72,0)),INDEX('SCORING MASTER'!$D$74:$D$75,MATCH(AO15,'SCORING MASTER'!$C$74:$C$75,0)),INDEX('SCORING MASTER'!$D$77:$D$78,MATCH(AP15,'SCORING MASTER'!$C$77:$C$78,0)))*20,0)) | BJ15: =IF(COUNTBLANK(AU15:AZ15)>0,"",ROUND(AVERAGE(INDEX('SCORING MASTER'!$D$95:$D$96,MATCH(AU15,'SCORING MASTER'!$C$95:$C$96,0)),INDEX('SCORING MASTER'!$D$98:$D$99,MATCH(AV15,'SCORING MASTER'!$C$98:$C$99,0)),INDEX('SCORING MASTER'!$D$101:$D$102,MATCH(AW15,'SCORING MASTER'!$C$101:$C$102,0)),INDEX('SCORING MASTER'!$D$104:$D$105,MATCH(AX15,'SCORING MASTER'!$C$104:$C$105,0)),INDEX('SCORING MASTER'!$D$107:$D$108,MATCH(AY15,'SCORING MASTER'!$C$107:$C$108,0)),INDEX('SCORING MASTER'!$D$110:$D$111,MATCH(AZ15,'SCORING MASTER'!$C$110:$C$111,0)))*20,0)) | BK15: =IF(COUNTBLANK(AQ15:AT15)>0,"",ROUND(AVERAGE(INDEX('SCORING MASTER'!$D$80:$D$82,MATCH(AQ15,'SCORING MASTER'!$C$80:$C$82,0)),INDEX('SCORING MASTER'!$D$84:$D$86,MATCH(AR15,'SCORING MASTER'!$C$84:$C$86,0)),INDEX('SCORING MASTER'!$D$88:$D$90,MATCH(AS15,'SCORING MASTER'!$C$88:$C$90,0)),INDEX('SCORING MASTER'!$D$92:$D$93,MATCH(AT15,'SCORING MASTER'!$C$92:$C$93,0)))*20,0)) | BL15: =IF(COUNTBLANK(BA15:BE15)>0,"",ROUND(AVERAGE(INDEX('SCORING MASTER'!$D$113:$D$115,MATCH(BA15,'SCORING MASTER'!$C$113:$C$115,0)),INDEX('SCORING MASTER'!$D$117:$D$119,MATCH(BB15,'SCORING MASTER'!$C$117:$C$119,0)),INDEX('SCORING MASTER'!$D$121:$D$123,MATCH(BC15,'SCORING MASTER'!$C$121:$C$123,0)),INDEX('SCORING MASTER'!$D$125:$D$126,MATCH(BD15,'SCORING MASTER'!$C$125:$C$126,0)),INDEX('SCORING MASTER'!$D$128:$D$129,MATCH(BE15,'SCORING MASTER'!$C$128:$C$129,0)))*20,0)) | BM15: =IF(OR(BF15="",BG15="",BH15="",BI15="",BJ15="",BK15="",BL15=""),"",ROUND(BF15*0.25+BG15*0.2+BH15*0.15+BI15*0.15+BJ15*0.1+BK15*0.1+BL15*0.05,0)) | BN15: =IF(OR(BF15="",BG15=""),"",ROUND(BF15*0.5+BG15*0.5,0)) | BO15: =IF(BN15="","",ROUND(MIN(100,MAX(0,(100-BN15)+IF(AL15="Yes",15,0)+IF(AM15="Yes",15,0)+IF(AND(U15<>"",U15<18.5),20,0))),0)) | BP15: =IF(BM15="","",IF(BM15>=90,"Green - Healthy",IF(BM15>=75,"Light Green - Mild Watch",IF(BM15>=60,"Yellow - Mild Risk",IF(BM15>=40,"Orange - Moderate Risk","Red - High Risk"))))) | BQ15: =IF(BM15="","",IF(OR(BM15<60,BO15>=60,AJ15="Yes"),"Yes","No")) | BR15: =IF(BM15="","",IF(OR(BP15="Orange - Moderate Risk",BP15="Red - High Risk",BQ15="Yes"),"Yes","No"))
